Workbook

Sheet Калькулятор (РУС)
A1: № | B1: Цена на единицу товара | C1: Категория 1 | D1: Категория 4 | E1: Габаритная группа (мгт/сгт/кгт) | F1: Процент Комиссии (%) | G1: Логистический Сбор | H1: Сумма комиссии | I1: Итоговая сумма (комиссия и логистика) | J1: Выручка на единицу товара с учетом комиссии и логистики | K1: Себестоимость товара | L1: Чистая выручка на единицу товара с учетом себестоимости и всех расходов
A2: 1 | B2: 50000 | C2: Автотовары | D2: Чехлы для колес | E2: СГТ | F2: =IFERROR(VLOOKUP(D2,'Комиссия за продажу (РУС)'!E:F,2,0),"") -> 0.3 | G2: =IFERROR(IF(E2="МГТ",IF(B2>100000,6000,IF(B2>10000,4000,2000)),IF(E2="СГТ",8000,20000)),"") -> 8000 | H2: =IFERROR(B2*F2,"") -> 15000 | I2: =G2+H2 -> 23000 | J2: =IFERROR(B2-I2,"") -> 27000 | K2: 30000 | L2: =IFERROR(B2-I2-K2,"") -> -3000 | N2: не трогать
A3: 2 | B3: 890000 | C3: Автотовары | D3: Умные часы | E3: МГТ | F3: =IFERROR(VLOOKUP(D3,'Комиссия за продажу (РУС)'!E:F,2,0),"") -> 0.17 | G3: =IFERROR(IF(E3="МГТ",IF(B3>100000,6000,IF(B3>10000,4000,2000)),IF(E3="СГТ",8000,20000)),"") -> 6000 | H3: =IFERROR(B3*F3,"") -> 151300 | I3: =G3+H3 -> 157300 | J3: =IFERROR(B3-I3,"") -> 732700 | K3: 458000 | L3: =IFERROR(B3-I3-K3,"") -> 274700 | N3: обязательно к заполнению
A4: 3 | B4: 4580000 | C4: Автотовары | D4: Холодильники | E4: КГТ | F4: =IFERROR(VLOOKUP(D4,'Комиссия за продажу (РУС)'!E:F,2,0),"") -> 0.1 | G4: =IFERROR(IF(E4="МГТ",IF(B4>100000,6000,IF(B4>10000,4000,2000)),IF(E4="СГТ",8000,20000)),"") -> 20000 | H4: =IFERROR(B4*F4,"") -> 458000 | I4: =G4+H4 -> 478000 | J4: =IFERROR(B4-I4,"") -> 4102000 | K4: 2100000 | L4: =IFERROR(B4-I4-K4,"") -> 2002000 | N4: необязательно к заполнению
A5: 4 | B5: 10000000 | C5: Автотовары | D5: Xbox | E5: СГТ | F5: =IFERROR(VLOOKUP(D5,'Комиссия за продажу (РУС)'!E:F,2,0),"") -> 0.1 | G5: =IFERROR(IF(E5="МГТ",IF(B5>100000,6000,IF(B5>10000,4000,2000)),IF(E5="СГТ",8000,20000)),"") -> 8000 | H5: =IFERROR(B5*F5,"") -> 1000000 | I5: =G5+H5 -> 1008000 | J5: =IFERROR(B5-I5,"") -> 8992000 | K5: 7000000 | L5: =IFERROR(B5-I5-K5,"") -> 1992000
A6: 5 | B6: 300000 | C6: Автотовары | D6: Геймпады, джойстики и триггеры | E6: СГТ | F6: =IFERROR(VLOOKUP(D6,'Комиссия за продажу (РУС)'!E:F,2,0),"") -> 0.15 | G6: =IFERROR(IF(E6="МГТ",IF(B6>100000,6000,IF(B6>10000,4000,2000)),IF(E6="СГТ",8000,20000)),"") -> 8000 | H6: =IFERROR(B6*F6,"") -> 45000 | I6: =G6+H6 -> 53000 | J6: =IFERROR(B6-I6,"") -> 247000 | K6: 200000 | L6: =IFERROR(B6-I6-K6,"") -> 47000
A7: 6 | C7: Автотовары | E7: КГТ | F7: =IFERROR(VLOOKUP(D7,'Комиссия за продажу (РУС)'!E:F,2,0),"") | G7: =IFERROR(IF(E7="МГТ",IF(B7>100000,6000,IF(B7>10000,4000,2000)),IF(E7="СГТ",8000,20000)),"") -> 20000 | H7: =IFERROR(B7*F7,"") | I7: =G7+H7 -> #VALUE! | J7: =IFERROR(B7-I7,"") | L7: =IFERROR(B7-I7-K7,"")
A8: 7 | C8: Автотовары | E8: КГТ | F8: =IFERROR(VLOOKUP(D8,'Комиссия за продажу (РУС)'!E:F,2,0),"") | G8: =IFERROR(IF(E8="МГТ",IF(B8>100000,6000,IF(B8>10000,4000,2000)),IF(E8="СГТ",8000,20000)),"") -> 20000 | H8: =IFERROR(B8*F8,"") | I8: =G8+H8 -> #VALUE! | J8: =IFERROR(B8-I8,"") | L8: =IFERROR(B8-I8-K8,"")
A9: 8 | C9: Автотовары | E9: КГТ | F9: =IFERROR(VLOOKUP(D9,'Комиссия за продажу (РУС)'!E:F,2,0),"") | G9: =IFERROR(IF(E9="МГТ",IF(B9>100000,6000,IF(B9>10000,4000,2000)),IF(E9="СГТ",8000,20000)),"") -> 20000 | H9: =IFERROR(B9*F9,"") | I9: =G9+H9 -> #VALUE! | J9: =IFERROR(B9-I9,"") | L9: =IFERROR(B9-I9-K9,"")
A10: 9 | C10: Автотовары | E10: КГТ | F10: =IFERROR(VLOOKUP(D10,'Комиссия за продажу (РУС)'!E:F,2,0),"") | G10: =IFERROR(IF(E10="МГТ",IF(B10>100000,6000,IF(B10>10000,4000,2000)),IF(E10="СГТ",8000,20000)),"") -> 20000 | H10: =IFERROR(B10*F10,"") | I10: =G10+H10 -> #VALUE! | J10: =IFERROR(B10-I10,"") | L10: =IFERROR(B10-I10-K10,"")
A11: 10 | C11: Автотовары | E11: КГТ | F11: =IFERROR(VLOOKUP(D11,'Комиссия за продажу (РУС)'!E:F,2,0),"") | G11: =IFERROR(IF(E11="МГТ",IF(B11>100000,6000,IF(B11>10000,4000,2000)),IF(E11="СГТ",8000,20000)),"") -> 20000 | H11: =IFERROR(B11*F11,"") | I11: =G11+H11 -> #VALUE! | J11: =IFERROR(B11-I11,"") | L11: =IFERROR(B11-I11-K11,"")
A12: 11 | C12: Автотовары | E12: КГТ | F12: =IFERROR(VLOOKUP(D12,'Комиссия за продажу (РУС)'!E:F,2,0),"") | G12: =IFERROR(IF(E12="МГТ",IF(B12>100000,6000,IF(B12>10000,4000,2000)),IF(E12="СГТ",8000,20000)),"") -> 20000 | H12: =IFERROR(B12*F12,"") | I12: =G12+H12 -> #VALUE! | J12: =IFERROR(B12-I12,"") | L12: =IFERROR(B12-I12-K12,"")
A13: 12 | C13: Автотовары | E13: КГТ | F13: =IFERROR(VLOOKUP(D13,'Комиссия за продажу (РУС)'!E:F,2,0),"") | G13: =IFERROR(IF(E13="МГТ",IF(B13>100000,6000,IF(B13>10000,4000,2000)),IF(E13="СГТ",8000,20000)),"") -> 20000 | H13: =IFERROR(B13*F13,"") | I13: =G13+H13 -> #VALUE! | J13: =IFERROR(B13-I13,"") | L13: =IFERROR(B13-I13-K13,"")
A14: 13 | C14: Автотовары | E14: КГТ | F14: =IFERROR(VLOOKUP(D14,'Комиссия за продажу (РУС)'!E:F,2,0),"") | G14: =IFERROR(IF(E14="МГТ",IF(B14>100000,6000,IF(B14>10000,4000,2000)),IF(E14="СГТ",8000,20000)),"") -> 20000 | H14: =IFERROR(B14*F14,"") | I14: =G14+H14 -> #VALUE! | J14: =IFERROR(B14-I14,"") | L14: =IFERROR(B14-I14-K14,"")
A15: 14 | C15: Автотовары | E15: КГТ | F15: =IFERROR(VLOOKUP(D15,'Комиссия за продажу (РУС)'!E:F,2,0),"") | G15: =IFERROR(IF(E15="МГТ",IF(B15>100000,6000,IF(B15>10000,4000,2000)),IF(E15="СГТ",8000,20000)),"") -> 20000 | H15: =IFERROR(B15*F15,"") | I15: =G15+H15 -> #VALUE! | J15: =IFERROR(B15-I15,"") | L15: =IFERROR(B15-I15-K15,"")
A16: 15 | C16: Автотовары | E16: КГТ | F16: =IFERROR(VLOOKUP(D16,'Комиссия за продажу (РУС)'!E:F,2,0),"") | G16: =IFERROR(IF(E16="МГТ",IF(B16>100000,6000,IF(B16>10000,4000,2000)),IF(E16="СГТ",8000,20000)),"") -> 20000 | H16: =IFERROR(B16*F16,"") | I16: =G16+H16 -> #VALUE! | J16: =IFERROR(B16-I16,"") | L16: =IFERROR(B16-I16-K16,"")
A17: 16 | C17: Автотовары | E17: КГТ | F17: =IFERROR(VLOOKUP(D17,'Комиссия за продажу (РУС)'!E:F,2,0),"") | G17: =IFERROR(IF(E17="МГТ",IF(B17>100000,6000,IF(B17>10000,4000,2000)),IF(E17="СГТ",8000,20000)),"") -> 20000 | H17: =IFERROR(B17*F17,"") | I17: =G17+H17 -> #VALUE! | J17: =IFERROR(B17-I17,"") | L17: =IFERROR(B17-I17-K17,"")
A18: 17 | C18: Автотовары | E18: КГТ | F18: =IFERROR(VLOOKUP(D18,'Комиссия за продажу (РУС)'!E:F,2,0),"") | G18: =IFERROR(IF(E18="МГТ",IF(B18>100000,6000,IF(B18>10000,4000,2000)),IF(E18="СГТ",8000,20000)),"") -> 20000 | H18: =IFERROR(B18*F18,"") | I18: =G18+H18 -> #VALUE! | J18: =IFERROR(B18-I18,"") | L18: =IFERROR(B18-I18-K18,"")
... A101: 100 | C101: Автотовары | E101: КГТ | F101: =IFERROR(VLOOKUP(D101,'Комиссия за продажу (РУС)'!E:F,2,0),"") | G101: =IFERROR(IF(E101="МГТ",IF(B101>100000,6000,IF(B101>10000,4000,2000)),IF(E101="СГТ",8000,20000)),"") -> 20000 | H101: =IFERROR(B101*F101,"") | I101: =G101+H101 -> #VALUE! | J101: =IFERROR(B101-I101,"") | L101: =IFERROR(B101-I101-K101,"")

Sheet Kalkulyator (UZB)
A1: № | B1: Tovar birligining narxi | C1: 1-toifa | D1: 4-toifa | E1: Gabarit guruhi (mgt/o‘gt/ygt) | F1: Komissiya Foizi (%) | G1: Logistika yig‘imi | H1: Komissiya summasi | I1: Umumiy summa (komissiya va logistika) | J1: Komissiya va logistikani hisobga olgan holda tovar birligidan olingan daromad | K1: Tovar tannarxi | L1: Tannarx va barcha xarajatlarni hisobga olgan holda tovar birligidan olingan sof daromad
A2: 1 | B2: 500000 | C2: Aksessuarlar | D2: Uzuklar | E2: MGT | F2: =IFERROR(VLOOKUP(D2,'Savdo komissiyasi (UZB)'!E:F,2,0),"") -> 0.3 | G2: =IFERROR(IF(E2="MGT",IF(B2>100000,6000,IF(B2>10000,4000,2000)),IF(E2="O'GT",8000,20000)),"") -> 6000 | H2: =IFERROR(B2*F2,"") -> 150000 | I2: =G2+H2 -> 156000 | J2: =IFERROR(B2-I2,"") -> 344000 | K2: 400000 | L2: =IFERROR(B2-I2-K2,"") -> -56000 | N2: tegish mumkin emas
A3: 2 | B3: 890000 | C3: Avtotovarlar | D3: Avtoturargoh uchun uskunalar | E3: O'GT | F3: =IFERROR(VLOOKUP(D3,'Savdo komissiyasi (UZB)'!E:F,2,0),"") -> 0.17 | G3: =IFERROR(IF(E3="MGT",IF(B3>100000,6000,IF(B3>10000,4000,2000)),IF(E3="O'GT",8000,20000)),"") -> 8000 | H3: =IFERROR(B3*F3,"") -> 151300 | I3: =G3+H3 -> 159300 | J3: =IFERROR(B3-I3,"") -> 730700 | K3: 560000 | L3: =IFERROR(B3-I3-K3,"") -> 170700 | N3: to‘ldirish shart
A4: 3 | B4: 30000 | C4: Sport va hordiq | D4: Mini trenajorlar | E4: MGT | F4: =IFERROR(VLOOKUP(D4,'Savdo komissiyasi (UZB)'!E:F,2,0),"") -> 0.1 | G4: =IFERROR(IF(E4="MGT",IF(B4>100000,6000,IF(B4>10000,4000,2000)),IF(E4="O'GT",8000,20000)),"") -> 4000 | H4: =IFERROR(B4*F4,"") -> 3000 | I4: =G4+H4 -> 7000 | J4: =IFERROR(B4-I4,"") -> 23000 | K4: 11000 | L4: =IFERROR(B4-I4-K4,"") -> 12000 | N4: to‘ldirish shart emas
A5: 4 | B5: 5000000 | C5: Aksessuarlar | D5: Samokatlar | E5: YGT | F5: =IFERROR(VLOOKUP(D5,'Savdo komissiyasi (UZB)'!E:F,2,0),"") -> 0.2 | G5: =IFERROR(IF(E5="MGT",IF(B5>100000,6000,IF(B5>10000,4000,2000)),IF(E5="O'GT",8000,20000)),"") -> 20000 | H5: =IFERROR(B5*F5,"") -> 1000000 | I5: =G5+H5 -> 1020000 | J5: =IFERROR(B5-I5,"") -> 3980000 | K5: 2360000 | L5: =IFERROR(B5-I5-K5,"") -> 1620000
A6: 5 | B6: 300000 | C6: Maishiy texnika | D6: Robot changyutgichlar | E6: O'GT | F6: =IFERROR(VLOOKUP(D6,'Savdo komissiyasi (UZB)'!E:F,2,0),"") -> 0.1 | G6: =IFERROR(IF(E6="MGT",IF(B6>100000,6000,IF(B6>10000,4000,2000)),IF(E6="O'GT",8000,20000)),"") -> 8000 | H6: =IFERROR(B6*F6,"") -> 30000 | I6: =G6+H6 -> 38000 | J6: =IFERROR(B6-I6,"") -> 262000 | K6: 150000 | L6: =IFERROR(B6-I6-K6,"") -> 112000
A7: 6 | C7: Aksessuarlar | E7: MGT | F7: =IFERROR(VLOOKUP(D7,'Savdo komissiyasi (UZB)'!E:F,2,0),"") | G7: =IFERROR(IF(E7="MGT",IF(B7>100000,6000,IF(B7>10000,4000,2000)),IF(E7="O'GT",8000,20000)),"") -> 2000 | H7: =IFERROR(B7*F7,"") | I7: =G7+H7 -> #VALUE! | J7: =IFERROR(B7-I7,"") | L7: =IFERROR(B7-I7-K7,"")
A8: 7 | C8: Aksessuarlar | E8: MGT | F8: =IFERROR(VLOOKUP(D8,'Savdo komissiyasi (UZB)'!E:F,2,0),"") | G8: =IFERROR(IF(E8="MGT",IF(B8>100000,6000,IF(B8>10000,4000,2000)),IF(E8="O'GT",8000,20000)),"") -> 2000 | H8: =IFERROR(B8*F8,"") | I8: =G8+H8 -> #VALUE! | J8: =IFERROR(B8-I8,"") | L8: =IFERROR(B8-I8-K8,"")
A9: 8 | C9: Aksessuarlar | E9: MGT | F9: =IFERROR(VLOOKUP(D9,'Savdo komissiyasi (UZB)'!E:F,2,0),"") | G9: =IFERROR(IF(E9="MGT",IF(B9>100000,6000,IF(B9>10000,4000,2000)),IF(E9="O'GT",8000,20000)),"") -> 2000 | H9: =IFERROR(B9*F9,"") | I9: =G9+H9 -> #VALUE! | J9: =IFERROR(B9-I9,"") | L9: =IFERROR(B9-I9-K9,"")
A10: 9 | C10: Aksessuarlar | E10: MGT | F10: =IFERROR(VLOOKUP(D10,'Savdo komissiyasi (UZB)'!E:F,2,0),"") | G10: =IFERROR(IF(E10="MGT",IF(B10>100000,6000,IF(B10>10000,4000,2000)),IF(E10="O'GT",8000,20000)),"") -> 2000 | H10: =IFERROR(B10*F10,"") | I10: =G10+H10 -> #VALUE! | J10: =IFERROR(B10-I10,"") | L10: =IFERROR(B10-I10-K10,"")
A11: 10 | C11: Aksessuarlar | E11: MGT | F11: =IFERROR(VLOOKUP(D11,'Savdo komissiyasi (UZB)'!E:F,2,0),"") | G11: =IFERROR(IF(E11="MGT",IF(B11>100000,6000,IF(B11>10000,4000,2000)),IF(E11="O'GT",8000,20000)),"") -> 2000 | H11: =IFERROR(B11*F11,"") | I11: =G11+H11 -> #VALUE! | J11: =IFERROR(B11-I11,"") | L11: =IFERROR(B11-I11-K11,"")
A12: 11 | C12: Aksessuarlar | E12: MGT | F12: =IFERROR(VLOOKUP(D12,'Savdo komissiyasi (UZB)'!E:F,2,0),"") | G12: =IFERROR(IF(E12="MGT",IF(B12>100000,6000,IF(B12>10000,4000,2000)),IF(E12="O'GT",8000,20000)),"") -> 2000 | H12: =IFERROR(B12*F12,"") | I12: =G12+H12 -> #VALUE! | J12: =IFERROR(B12-I12,"") | L12: =IFERROR(B12-I12-K12,"")
A13: 12 | C13: Aksessuarlar | E13: MGT | F13: =IFERROR(VLOOKUP(D13,'Savdo komissiyasi (UZB)'!E:F,2,0),"") | G13: =IFERROR(IF(E13="MGT",IF(B13>100000,6000,IF(B13>10000,4000,2000)),IF(E13="O'GT",8000,20000)),"") -> 2000 | H13: =IFERROR(B13*F13,"") | I13: =G13+H13 -> #VALUE! | J13: =IFERROR(B13-I13,"") | L13: =IFERROR(B13-I13-K13,"")
A14: 13 | C14: Aksessuarlar | E14: MGT | F14: =IFERROR(VLOOKUP(D14,'Savdo komissiyasi (UZB)'!E:F,2,0),"") | G14: =IFERROR(IF(E14="MGT",IF(B14>100000,6000,IF(B14>10000,4000,2000)),IF(E14="O'GT",8000,20000)),"") -> 2000 | H14: =IFERROR(B14*F14,"") | I14: =G14+H14 -> #VALUE! | J14: =IFERROR(B14-I14,"") | L14: =IFERROR(B14-I14-K14,"")
A15: 14 | C15: Aksessuarlar | E15: MGT | F15: =IFERROR(VLOOKUP(D15,'Savdo komissiyasi (UZB)'!E:F,2,0),"") | G15: =IFERROR(IF(E15="MGT",IF(B15>100000,6000,IF(B15>10000,4000,2000)),IF(E15="O'GT",8000,20000)),"") -> 2000 | H15: =IFERROR(B15*F15,"") | I15: =G15+H15 -> #VALUE! | J15: =IFERROR(B15-I15,"") | L15: =IFERROR(B15-I15-K15,"")
A16: 15 | C16: Aksessuarlar | E16: MGT | F16: =IFERROR(VLOOKUP(D16,'Savdo komissiyasi (UZB)'!E:F,2,0),"") | G16: =IFERROR(IF(E16="MGT",IF(B16>100000,6000,IF(B16>10000,4000,2000)),IF(E16="O'GT",8000,20000)),"") -> 2000 | H16: =IFERROR(B16*F16,"") | I16: =G16+H16 -> #VALUE! | J16: =IFERROR(B16-I16,"") | L16: =IFERROR(B16-I16-K16,"")
A17: 16 | C17: Aksessuarlar | E17: MGT | F17: =IFERROR(VLOOKUP(D17,'Savdo komissiyasi (UZB)'!E:F,2,0),"") | G17: =IFERROR(IF(E17="MGT",IF(B17>100000,6000,IF(B17>10000,4000,2000)),IF(E17="O'GT",8000,20000)),"") -> 2000 | H17: =IFERROR(B17*F17,"") | I17: =G17+H17 -> #VALUE! | J17: =IFERROR(B17-I17,"") | L17: =IFERROR(B17-I17-K17,"")
A18: 17 | C18: Aksessuarlar | E18: MGT | F18: =IFERROR(VLOOKUP(D18,'Savdo komissiyasi (UZB)'!E:F,2,0),"") | G18: =IFERROR(IF(E18="MGT",IF(B18>100000,6000,IF(B18>10000,4000,2000)),IF(E18="O'GT",8000,20000)),"") -> 2000 | H18: =IFERROR(B18*F18,"") | I18: =G18+H18 -> #VALUE! | J18: =IFERROR(B18-I18,"") | L18: =IFERROR(B18-I18-K18,"")
... A101: 100 | C101: Aksessuarlar | E101: MGT | F101: =IFERROR(VLOOKUP(D101,'Savdo komissiyasi (UZB)'!E:F,2,0),"") | G101: =IFERROR(IF(E101="MGT",IF(B101>100000,6000,IF(B101>10000,4000,2000)),IF(E101="O'GT",8000,20000)),"") -> 2000 | H101: =IFERROR(B101*F101,"") | I101: =G101+H101 -> #VALUE! | J101: =IFERROR(B101-I101,"") | L101: =IFERROR(B101-I101-K101,"")

Sheet Комиссия за продажу (РУС)
A3: cat_code | B3: category1 | C3: category2 | D3: category3 | E3: category4 | F3: comm %
A4: =B4&C4&D4&E4 -> ЗдоровьеОптикаАксессуары для линзАксессуары для линз | B4: Здоровье | C4: Оптика | D4: Аксессуары для линз | E4: Аксессуары для линз | F4: 0.35
A5: =B5&C5&D5&E5 -> ЗдоровьеОптикаСалфетки, спреи для очковСалфетки, спреи для очков | B5: Здоровье | C5: Оптика | D5: Салфетки, спреи для очков | E5: Салфетки, спреи для очков | F5: 0.35
A6: =B6&C6&D6&E6 -> ЗдоровьеОртопедические изделияОртопедические стельки и полустельки, корректоры стопыОртопедические стельки и полустельки, корректоры стопы | B6: Здоровье | C6: Ортопедические изделия | D6: Ортопедические стельки и полустельки, корректоры стопы | E6: Ортопедические стельки и полустельки, корректоры стопы | F6: 0.35
A7: =B7&C7&D7&E7 -> ЭлектроникаОфисная техникаКомплектующие для офисной техникиФотобарабаны | B7: Электроника | C7: Офисная техника | D7: Комплектующие для офисной техники | E7: Фотобарабаны | F7: 0.3
A8: =B8&C8&D8&E8 -> Товары для домаТовары для праздниковОформление праздникаФотобутафория | B8: Товары для дома | C8: Товары для праздников | D8: Оформление праздника | E8: Фотобутафория | F8: 0.3
A9: =B9&C9&D9&E9 -> АксессуарыМужские аксессуарыКошельки, ключницы и визитницыЗажимы для денег | B9: Аксессуары | C9: Мужские аксессуары | D9: Кошельки, ключницы и визитницы | E9: Зажимы для денег | F9: 0.3
A10: =B10&C10&D10&E10 -> ЭлектроникаСмартфоны и телефоныАксессуары для смартфоновШнурки | B10: Электроника | C10: Смартфоны и телефоны | D10: Аксессуары для смартфонов | E10: Шнурки | F10: 0.3
A11: =B11&C11&D11&E11 -> ЗдоровьеОртопедические изделияКомпрессионный трикотажКомпрессионные чулки | B11: Здоровье | C11: Ортопедические изделия | D11: Компрессионный трикотаж | E11: Компрессионные чулки | F11: 0.3
A12: =B12&C12&D12&E12 -> Бытовая техникаТовары для кухниПрочая кухонная техникаЛанчбоксы с подогревом | B12: Бытовая техника | C12: Товары для кухни | D12: Прочая кухонная техника | E12: Ланчбоксы с подогревом | F12: 0.3
A13: =B13&C13&D13&E13 -> Красота и уходМакияжАксессуары для макияжаПовязки косметические | B13: Красота и уход | C13: Макияж | D13: Аксессуары для макияжа | E13: Повязки косметические | F13: 0.3
A14: =B14&C14&D14&E14 -> ЭлектроникаОфисная техникаКомплектующие для офисной техникиЧернила | B14: Электроника | C14: Офисная техника | D14: Комплектующие для офисной техники | E14: Чернила | F14: 0.3
A15: =B15&C15&D15&E15 -> ЭлектроникаНоутбуки, планшеты и электронные книгиАксессуары для ноутбуковЗапчасти для ноутбуков | B15: Электроника | C15: Ноутбуки, планшеты и электронные книги | D15: Аксессуары для ноутбуков | E15: Запчасти для ноутбуков | F15: 0.3
... A2875: =B2875&C2875&D2875&E2875 -> ЗдоровьеТовары для реабилитацииИнвалидные коляскиИнвалидные коляски | B2875: Здоровье | C2875: Товары для реабилитации | D2875: Инвалидные коляски | E2875: Инвалидные коляски | F2875: 0.01

Sheet Savdo komissiyasi (UZB)
B1: ,
A3: cat_code | B3: category1 | C3: category2 | D3: category3 | E3: category4 | F3: comm % | K3: category1 (Do not touch)
A4: =B4&C4&D4&E4 -> SalomatlikOrtopedik buyumlarOrtopedik tagliklar va yarim tagliklar, oyoq tuzatuvchisiOrtopedik tagliklar va yarim tagliklar, oyoq tuzatuvchisi | B4: Salomatlik | C4: Ortopedik buyumlar | D4: Ortopedik tagliklar va yarim tagliklar, oyoq tuzatuvchisi | E4: Ortopedik tagliklar va yarim tagliklar, oyoq tuzatuvchisi | F4: 0.35 | K4: Aksessuarlar
A5: =B5&C5&D5&E5 -> SalomatlikOptikaLinza uchun aksessuarlarLinza uchun aksessuarlar | B5: Salomatlik | C5: Optika | D5: Linza uchun aksessuarlar | E5: Linza uchun aksessuarlar | F5: 0.35 | K5: Avtotovarlar
A6: =B6&C6&D6&E6 -> SalomatlikOptikaSalfetkalar, koʻzoynak uchun spreylarSalfetkalar, koʻzoynak uchun spreylar | B6: Salomatlik | C6: Optika | D6: Salfetkalar, koʻzoynak uchun spreylar | E6: Salfetkalar, koʻzoynak uchun spreylar | F6: 0.35 | K6: Bolalar tovarlari
A7: =B7&C7&D7&E7 -> AksessuarlarErkaklar aksessuarlariHamyonlar, kalit solgichlar va tashrif qogʻozi uchun karmonchalarPul uchun qistirgichlar | B7: Aksessuarlar | C7: Erkaklar aksessuarlari | D7: Hamyonlar, kalit solgichlar va tashrif qogʻozi uchun karmonchalar | E7: Pul uchun qistirgichlar | F7: 0.3 | K7: Dacha, bogʻ va tomorqa
A8: =B8&C8&D8&E8 -> AksessuarlarSayohat uchun aksessuarlarChamadonlar uchun aksessuarlarChamadon uchun qulflar | B8: Aksessuarlar | C8: Sayohat uchun aksessuarlar | D8: Chamadonlar uchun aksessuarlar | E8: Chamadon uchun qulflar | F8: 0.3 | K8: Elektronika
A9: =B9&C9&D9&E9 -> AksessuarlarAyollar aksessuarlariBijuteriyalarBoʻyinga taqiladigan taqinchoqlar | B9: Aksessuarlar | C9: Ayollar aksessuarlari | D9: Bijuteriyalar | E9: Boʻyinga taqiladigan taqinchoqlar | F9: 0.3 | K9: Goʻzallik va parvarish
A10: =B10&C10&D10&E10 -> AksessuarlarErkaklar aksessuarlariZargarlik buyumlariZanjirlar | B10: Aksessuarlar | C10: Erkaklar aksessuarlari | D10: Zargarlik buyumlari | E10: Zanjirlar | F10: 0.3 | K10: Hayvonlar uchun tovarlar
A11: =B11&C11&D11&E11 -> AksessuarlarErkaklar aksessuarlariZargarlik buyumlariBilaguzuklar | B11: Aksessuarlar | C11: Erkaklar aksessuarlari | D11: Zargarlik buyumlari | E11: Bilaguzuklar | F11: 0.3 | K11: Kanselyariya tovarlari
A12: =B12&C12&D12&E12 -> AksessuarlarSayohat uchun aksessuarlarChamadonlar uchun aksessuarlarChamadon uchun gʻiloflar | B12: Aksessuarlar | C12: Sayohat uchun aksessuarlar | D12: Chamadonlar uchun aksessuarlar | E12: Chamadon uchun gʻiloflar | F12: 0.3 | K12: Kitoblar
A13: =B13&C13&D13&E13 -> AksessuarlarErkaklar aksessuarlariBoʻyinbogʻlar, kapalakchalar, roʻmolchalarKapalakcha boʻyinbogʻlar | B13: Aksessuarlar | C13: Erkaklar aksessuarlari | D13: Boʻyinbogʻlar, kapalakchalar, roʻmolchalar | E13: Kapalakcha boʻyinbogʻlar | F13: 0.3 | K13: Kiyim
A14: =B14&C14&D14&E14 -> AksessuarlarErkaklar aksessuarlariBosh kiyimlarKepkalar va beysbol qalpoqlari | B14: Aksessuarlar | C14: Erkaklar aksessuarlari | D14: Bosh kiyimlar | E14: Kepkalar va beysbol qalpoqlari | F14: 0.3 | K14: Maishiy kimyoviy moddalar
A15: =B15&C15&D15&E15 -> AksessuarlarErkaklar aksessuarlariBijuteriyalarBilaguzuklar | B15: Aksessuarlar | C15: Erkaklar aksessuarlari | D15: Bijuteriyalar | E15: Bilaguzuklar | F15: 0.3 | K15: Maishiy texnika
... A23: =B23&C23&D23&E23 -> AksessuarlarSayohat uchun aksessuarlarYoʻl sumkalariYoʻl sumkalari | B23: Aksessuarlar | C23: Sayohat uchun aksessuarlar | D23: Yoʻl sumkalari | E23: Yoʻl sumkalari | F23: 0.3 | K23: Xobbi va ijod
A24: =B24&C24&D24&E24 -> AksessuarlarAyollar aksessuarlariQoʻlqoplar va varejkalarYenglar | B24: Aksessuarlar | C24: Ayollar aksessuarlari | D24: Qoʻlqoplar va varejkalar | E24: Yenglar | F24: 0.3
A25: =B25&C25&D25&E25 -> AksessuarlarAyollar aksessuarlariRoʻmolar va sharflarSharflar | B25: Aksessuarlar | C25: Ayollar aksessuarlari | D25: Roʻmolar va sharflar | E25: Sharflar | F25: 0.3
A26: =B26&C26&D26&E26 -> AksessuarlarErkaklar aksessuarlariRoʻmolchalar va sharflarSharflar | B26: Aksessuarlar | C26: Erkaklar aksessuarlari | D26: Roʻmolchalar va sharflar | E26: Sharflar | F26: 0.3
A27: =B27&C27&D27&E27 -> AksessuarlarAyollar aksessuarlariKoʻzoynakKoʻzoynak uchun qutilar va gʻiloflar | B27: Aksessuarlar | C27: Ayollar aksessuarlari | D27: Koʻzoynak | E27: Koʻzoynak uchun qutilar va gʻiloflar | F27: 0.3
A28: =B28&C28&D28&E28 -> AksessuarlarErkaklar aksessuarlariKoʻzoynakKompyuter uchun ko'zoynaklar | B28: Aksessuarlar | C28: Erkaklar aksessuarlari | D28: Koʻzoynak | E28: Kompyuter uchun ko'zoynaklar | F28: 0.3
A29: =B29&C29&D29&E29 -> AksessuarlarErkaklar aksessuarlariQoʻlqoplar va varejkalarQoʻlqoplar | B29: Aksessuarlar | C29: Erkaklar aksessuarlari | D29: Qoʻlqoplar va varejkalar | E29: Qoʻlqoplar | F29: 0.3
A30: =B30&C30&D30&E30 -> AksessuarlarAyollar aksessuarlariKlatchlar va kosmetika sumkalarKlatchlar | B30: Aksessuarlar | C30: Ayollar aksessuarlari | D30: Klatchlar va kosmetika sumkalar | E30: Klatchlar | F30: 0.3
A31: =B31&C31&D31&E31 -> AksessuarlarAyollar aksessuarlariZargarlik buyumlariBoʻyinga taqiladigan taqinchoqlar | B31: Aksessuarlar | C31: Ayollar aksessuarlari | D31: Zargarlik buyumlari | E31: Boʻyinga taqiladigan taqinchoqlar | F31: 0.3
A32: =B32&C32&D32&E32 -> AksessuarlarAyollar aksessuarlariBosh kiyimlarShlyapalar | B32: Aksessuarlar | C32: Ayollar aksessuarlari | D32: Bosh kiyimlar | E32: Shlyapalar | F32: 0.3
A33: =B33&C33&D33&E33 -> AksessuarlarAyollar aksessuarlariZargarlik buyumlariBilaguzuklar | B33: Aksessuarlar | C33: Ayollar aksessuarlari | D33: Zargarlik buyumlari | E33: Bilaguzuklar | F33: 0.3
A34: =B34&C34&D34&E34 -> AksessuarlarAyollar aksessuarlariHamyonlar, kalit solgichlar va tashrif qogʻozi uchun karmonchalarPul uchun qisqichlar | B34: Aksessuarlar | C34: Ayollar aksessuarlari | D34: Hamyonlar, kalit solgichlar va tashrif qogʻozi uchun karmonchalar | E34: Pul uchun qisqichlar | F34: 0.3
A35: =B35&C35&D35&E35 -> AksessuarlarErkaklar aksessuarlariZargarlik buyumlariZiraklar | B35: Aksessuarlar | C35: Erkaklar aksessuarlari | D35: Zargarlik buyumlari | E35: Ziraklar | F35: 0.3
... A209: =B209&C209&D209&E209 -> ElektronikaSmartfonlar va telefonlarSmartfonlar uchun aksessuarlarXotira kartalari telefonlar uchun | B209: Elektronika | C209: Smartfonlar va telefonlar | D209: Smartfonlar uchun aksessuarlar | E209: Xotira kartalari telefonlar uchun | F209: 0.3
A210: =B210&C210&D210&E210 -> ElektronikaQuloqchinlar va audio texnikalarProigrivatel uchun aksessuarlarParvarish uchun tovarlar | B210: Elektronika | C210: Quloqchinlar va audio texnikalar | D210: Proigrivatel uchun aksessuarlar | E210: Parvarish uchun tovarlar | F210: 0.3 | I210: 90000
A211: =B211&C211&D211&E211 -> ElektronikaSmartfonlar va telefonlarSmartfonlar uchun aksessuarlarHimoya shishalari va plyonkalar | B211: Elektronika | C211: Smartfonlar va telefonlar | D211: Smartfonlar uchun aksessuarlar | E211: Himoya shishalari va plyonkalar | F211: 0.3 | I211: 0.35 | J211: 0.3
A212: =B212&C212&D212&E212 -> ElektronikaFoto va video texnikaFoto va video kameralar uchun aksessuarlarSumkalar va ryukzaklar | B212: Elektronika | C212: Foto va video texnika | D212: Foto va video kameralar uchun aksessuarlar | E212: Sumkalar va ryukzaklar | F212: 0.3 | J212: 4000
A213: =B213&C213&D213&E213 -> ElektronikaSmartfonlar va telefonlarStatsionar telefonlarSimli telefonlar | B213: Elektronika | C213: Smartfonlar va telefonlar | D213: Statsionar telefonlar | E213: Simli telefonlar | F213: 0.3 | J213: =J212/I210 -> 0.044444444
A214: =B214&C214&D214&E214 -> ElektronikaNoutbuklar, planshetlar va elektron kitoblarNoutbuk uchun aksessuarlarNoutbuklar uchun ehtiyot qismlar | B214: Elektronika | C214: Noutbuklar, planshetlar va elektron kitoblar | D214: Noutbuk uchun aksessuarlar | E214: Noutbuklar uchun ehtiyot qismlar | F214: 0.3
A215: =B215&C215&D215&E215 -> ElektronikaKompyuter texnikasiKompyuter texnikalari uchun butlovchi qismlarKompyuterlar uchun sovutish tizimlari | B215: Elektronika | C215: Kompyuter texnikasi | D215: Kompyuter texnikalari uchun butlovchi qismlar | E215: Kompyuterlar uchun sovutish tizimlari | F215: 0.3
A216: =B216&C216&D216&E216 -> ElektronikaElektronikalar uchun aksessuarlarElektr tarmoqlagichlarElektr tarmoqlagichlar | B216: Elektronika | C216: Elektronikalar uchun aksessuarlar | D216: Elektr tarmoqlagichlar | E216: Elektr tarmoqlagichlar | F216: 0.3
A217: =B217&C217&D217&E217 -> ElektronikaNoutbuklar, planshetlar va elektron kitoblarPlanshetlar va elektron kitoblarPlanshetlar va elektron kitoblar uchun aksessuarlar | B217: Elektronika | C217: Noutbuklar, planshetlar va elektron kitoblar | D217: Planshetlar va elektron kitoblar | E217: Planshetlar va elektron kitoblar uchun aksessuarlar | F217: 0.3
A218: =B218&C218&D218&E218 -> ElektronikaQuloqchinlar va audio texnikalarQuloqchinlarQuloqchinlar uchun aksessuarlar | B218: Elektronika | C218: Quloqchinlar va audio texnikalar | D218: Quloqchinlar | E218: Quloqchinlar uchun aksessuarlar | F218: 0.3
A219: =B219&C219&D219&E219 -> Goʻzallik va parvarishMakiyajMakiyaj uchun aksessuarlarKosmetika bogʻichlari | B219: Goʻzallik va parvarish | C219: Makiyaj | D219: Makiyaj uchun aksessuarlar | E219: Kosmetika bogʻichlari | F219: 0.3
A220: =B220&C220&D220&E220 -> Goʻzallik va parvarishMakiyajMakiyaj uchun aksessuarlarSponji va aplikatorlar | B220: Goʻzallik va parvarish | C220: Makiyaj | D220: Makiyaj uchun aksessuarlar | E220: Sponji va aplikatorlar | F220: 0.3
A221: =B221&C221&D221&E221 -> Goʻzallik va parvarishMakiyajMakiyaj uchun aksessuarlarKosmetik oynalar | B221: Goʻzallik va parvarish | C221: Makiyaj | D221: Makiyaj uchun aksessuarlar | E221: Kosmetik oynalar | F221: 0.3
...

Sheet Логистический СборLogistika tol
A1: МГТ | D1: СГТ | E1: КГТ
A2: цена <10 тыс. сум | B2: цена 10-99 тыс. сум | C2: цена 100 тыс. сум и выше
A3: 2000 | B3: 4000 | C3: 6000 | D3: 8000 | E3: 20000
A6: MGT | D6: O'GT | E6: YGT
A7: narx <10 ming so‘m | B7: narx 10-99 ming so‘m | C7: narx 100 ming so‘m va undan yuqori
A8: 2000 | B8: 4000 | C8: 6000 | D8: 8000 | E8: 20000

Sheet Лист1
A1: Бытовая техника | D1: Aksessuarlar | G1: МГТ
A2: Электроника | D2: Avtotovarlar | G2: СГТ
A3: Аксессуары | D3: Bolalar tovarlari | G3: КГТ
A4: Обувь | D4: Dacha, bogʻ va tomorqa
A5: Одежда | D5: Elektronika | G5: MGT
A6: Детсткая одежда и обувь | D6: Goʻzallik va parvarish | G6: O'GT
A7: Бытовая химия | D7: Hayvonlar uchun tovarlar | G7: YGT
A8: Детсткие товары | D8: Kanselyariya tovarlari
A9: Здоровье | D9: Kitoblar
A10: Зоотовары | D10: Kiyim
A11: Красота и уход | D11: Maishiy kimyoviy moddalar
A12: Продукты питания | D12: Maishiy texnika
A13: Автотовары | D13: Oziq-ovqat mahsulotlari
A14: Дача сад и огород | D14: Poyabzallar
A15: Канцтовары | D15: Qurilish va taʼmirlash
A16: Книги | D16: Reabilitatsiya uchun subsidiyalangan tovarlar
A17: Спорт и отдых | D17: Salomatlik
A18: Строительство и ремонт | D18: Sport va hordiq
A19: Товары для дома | D19: Uy-roʻzgʻor buyumlari
A20: Хобби и творчество | D20: Xobbi va ijod
A21: Товары для реабилитации
